Workbook
Name _9000_Titolare_Effettivo_Cliente_1: #REF!
Name _90Imprese: 'Imprese_File clean'!$A$2:$V$12
Name _90Imprese: 'Imprese_File completo'!$A$2:$V$1833
Name _90LegaliRappresentanti: LegaliRappresentanti!$B$1:$Q$1906
Name Agric_20131128_114925: #REF!
Name Dati: #REF!
Name FARNELL: #REF!
Name Fiorini1: #REF!
Name Fiorini2: #REF!
Name MAROTTA: #REF!

Sheet Imprese_File completo
A1: DATI SOCIETA' | X1: DATI RAPPRESENTANTE LEGALE | AM1: CONTATTI
A2: 99 | B2: RAGIONE SOCIALE | C2: _PIVA | D2: _CF | E2: SEDE | F2: Posizione incrociata | G2: Posizione Duplicata | H2: Crif Number | I2: Denominazione | J2: Partita Iva | K2: REA | L2: CCIAA | M2: Codice fiscale | N2: Indirizzo | O2: Cap | P2: Comune | Q2: Frazione | R2: Provincia | S2: Regione | T2: Stato Impresa Cribis | U2: Natura giuridica | V2: Tipo natura giuridica | X2: Cognome Esponente | Y2: Nome Esponente | Z2: Sesso | AA2: Data di nascita | AB2: Provincia di Nascita | AC2: Comune di Nascita | AD2: Nazione di Nascita | AE2: Cittadinanza | AF2: Indirizzo | AG2: CAP | AH2: Comune | AI2: Provincia | AJ2: Frazione | AK2: Altre indicazioni | AL2: Nazione | AM2: Telefono | AN2: Email | AO2: PEC
A3: 99008921 | B3: LOMBARDO FRANCESCO | C3: 00125710863 | D3: LMBFNC54T28E536A | E3: CORSO UMBERTO 466/A - 94013 LEONFORTE EN | F3: Y | H3: ITDE420E04S0001 | I3: LOMBARDO FRANCESCO | J3: 00125710863 | K3: 30055 | L3: EN | M3: LMBFNC54T28E536A | N3: CORSO UMBERTO I 466/A | O3: 94013 | P3: LEONFORTE | R3: EN | S3: SICILIA | T3: Attiva | U3: IMPRESA INDIVIDUALE | V3: IMPRESE INDIVIDUALI | X3: LOMBARDO | Y3: FRANCESCO | Z3: M | AA3: 28/12/1954 | AB3: EN | AC3: LEONFORTE | AD3: IT | AE3: 0 | AF3: CORSO UMBERTO 564 | AG3: 94013 | AH3: LEONFORTE | AI3: EN | AJ3: 0 | AK3: 0 | AL3: IT | AM3: 0935903233 - 3200804175 GI | AN3: pino.lom88@gmail.com; | AO3: -
A4: 99000087 | B4: TABACCHERIA FONTANADI URIA MULLONI | C4: 00186950317 | D4: RMLNNL60M61E098K | E4: Via P. Signorini 12 - 34170 Gorizia GO | F4: Y | H4: ITAC850C00S0001 | I4: TABACCHERIA FONTANA DI URIA MULLONI ANTONELLA | J4: 00186950317 | K4: 49689 | L4: GO | M4: RMLNNL60M61E098K | N4: VIA SIGNORINI PAOLO 12 | O4: 34170 | P4: GORIZIA | R4: GO | S4: FRIULI-VENEZIA GIULIA | T4: Attiva | U4: IMPRESA INDIVIDUALE | V4: IMPRESE INDIVIDUALI | X4: URIA MULLONI | Y4: ANTONELLA | Z4: F | AA4: 21/08/1960 | AB4: GO | AC4: GORIZIA | AD4: IT | AE4: 0 | AF4: VIA GRADISCA 14 | AG4: 34070 | AH4: MARIANO DEL FRIULI | AI4: GO | AJ4: 0 | AK4: 0 | AL4: 0 | AM4: 048122125 - 3483419322 | AN4: xshana@libero.it; | AO4: -
A5: 99000094 | B5: IOVINO ETTORE CIRORIV. GENERI MONOP | C5: 00211620943 | D5: VNITRC61R14E335C | E5: Via Tedeschi 19 - 86170 Isernia IS | F5: Y | H5: ITF20D000CS0001 | I5: IOVINO ETTORE CIRO | J5: 00211620943 | K5: 23271 | L5: IS | M5: VNITRC61R14E335C | N5: VIA GIULIO TEDESCHI | O5: 86170 | P5: ISERNIA | R5: IS | S5: MOLISE | T5: Attiva | U5: IMPRESA INDIVIDUALE | V5: IMPRESE INDIVIDUALI | X5: IOVINO | Y5: ETTORE CIRO | Z5: M | AA5: 14/10/1961 | AB5: IS | AC5: ISERNIA | AD5: IT | AE5: 0 | AF5: VIA TOSCANINI 14 | AG5: 86170 | AH5: ISERNIA | AI5: IS | AJ5: 0 | AK5: 0 | AL5: 0 | AM5: 0865411908 - 3291413260 | AN5: ettoreciro.iovino1@tin.it; | AO5: -
A6: 99014497 | B6: FABIANO VITO | C6: 00235220563 | D6: FBNVTT45M02B776Y | E6: REPUBBLICA - 01023 BOLSENA | F6: Y | H6: IT9ECE0302S0001 | J6: 00235220563 | K6: 57730 | L6: VT | M6: FBNVTI45M02B776Y | T6: Cessata favorevole | U6: IMPRESA INDIVIDUALE | V6: IMPRESE INDIVIDUALI | X6: - | Y6: - | Z6: - | AA6: - | AB6: - | AC6: - | AD6: - | AE6: - | AF6: - | AG6: - | AH6: - | AI6: - | AJ6: - | AK6: - | AL6: - | AM6: 3202467716 | AN6: VANNI.TUSCIA@GMAIL.COM; | AO6: -
A7: 99015296 | B7: ALTOBELLO VINCENZA | C7: 00245590799 | D7: LTBVCN43L59C352T | E7: LE V.GATTOLEO/ - 88100 CATANZARO | F7: Y | H7: IT9321010AS0001 | I7: ALTOBELLO VINCENZA | J7: 00245590799 | K7: 75377 | L7: CZ | M7: LTBVCN43L59C352T | N7: VIALE VINCENZO GATTOLEO 20 | O7: 88100 | P7: CATANZARO | R7: CZ | S7: CALABRIA | T7: Attiva | U7: IMPRESA INDIVIDUALE | V7: IMPRESE INDIVIDUALI | X7: ALTOBELLO | Y7: VINCENZA | Z7: F | AA7: 19/07/1943 | AB7: CZ | AC7: CATANZARO | AD7: IT | AE7: 0 | AF7: VIALE VINCENZO GATTOLEO 20 | AG7: 88100 | AH7: CATANZARO | AI7: CZ | AJ7: 0 | AK7: 0 | AL7: 0 | AM7: 3336263880 | AN7: vincenzaaltobello@gmail.com; | AO7: -
A8: 99000567 | B8: S.A.M.A.C. DI ERMANNO MORI & C. SNC | C8: 00410540439 | D8: 00410540439 | E8: Contrada Asola 24 - 62012 Civitanova Marche MC | F8: Y | H8: IT6389090DS0001 | I8: S.A.M.A.C. DI MORI ERMANNO E FRATELLI SNC | J8: 00410540439 | K8: 90988 | L8: MC | M8: 00410540439 | N8: CONTRADA ASOLA 24 | O8: 62012 | P8: CIVITANOVA MARCHE | R8: MC | S8: MARCHE | T8: Attiva | U8: SOCIETA' IN NOME COLLETTIVO | V8: SOCIETA' DI PERSONE | X8: MORI | Y8: ALESSANDRA | Z8: F | AA8: 10/07/1966 | AB8: RM | AC8: ROMA | AD8: IT | AE8: 0 | AF8: VIA AURORA 67 | AG8: 62012 | AH8: CIVITANOVA MARCHE | AI8: MC | AJ8: 0 | AK8: 0 | AL8: IT | AM8: 07331871624 - 3282696668 PA | AN8: info@ippocivitanova.it; | AO8: -
A9: 99013241 | B9: BAR CENTRALE S.N.C. DEI FRATELLI SILVANO E MARIO GROSSI | C9: 00429820673 | D9: 00429820673 | E9: PIAZZA DELLA LIBERTA' 15, 64025, PINETO (TE) | F9: Y | H9: IT788F0704S0001 | I9: BAR CENTRALE S.N.C. DEI FRATELLI SILVANO E MARIO GROSSI | J9: 00429820673 | K9: 75112 | L9: TE | M9: 00429820673 | N9: PIAZZA DELLA LIBERTA' 13 | O9: 64025 | P9: PINETO | R9: TE | S9: ABRUZZO | T9: Attiva | U9: SOCIETA' IN NOME COLLETTIVO | V9: SOCIETA' DI PERSONE | X9: GROSSI | Y9: ALEXANDER | Z9: M | AA9: 09/06/1987 | AB9: TE | AC9: ATRI | AD9: 0 | AE9: 0 | AF9: VIA DE LITIO 4 | AG9: 64025 | AH9: PINETO | AI9: TE | AJ9: 0 | AK9: 0 | AL9: IT | AM9: 0859492441 | AN9: barcentrale1985@yahoo.it; | AO9: -
A10: 99015559 | B10: PERITO ROSA | C10: 00433790797 | D10: prtrso47e56c352l | E10: LUNGOMARE - 88100 CATANZARO | F10: Y | H10: ITB14E050BS0001 | I10: PERITO ROSA | J10: 00433790797 | K10: 150509 | L10: CZ | M10: PRTRSO47E56C352L | N10: VIA LUNGOMARE STEFANO PUGLIESE 239-245 | O10: 88100 | P10: CATANZARO | R10: CZ | S10: CALABRIA | T10: Attiva | U10: IMPRESA INDIVIDUALE | V10: IMPRESE INDIVIDUALI | X10: PERITO | Y10: ROSA | Z10: F | AA10: 16/05/1947 | AB10: CZ | AC10: CATANZARO | AD10: IT | AE10: 0 | AF10: VIA LUNGOMARE 271 LIDO | AG10: 88100 | AH10: CATANZARO | AI10: CZ | AJ10: 0 | AK10: 0 | AL10: 0 | AM10: - | AN10: stefanofebbraro@alice.it; | AO10: -
A11: 99004992 | B11: BAR STAZIONE SAS DI INTELLINI GIANN | C11: 00593580673 | D11: 00593580673 | E11: PIAZZALE STAZIONE FF.SS. - 64026 ROSETO DEGLI ABRUZZI TE | F11: Y | H11: IT9FAD0C0CS0001 | I11: BAR STAZIONE SAS DI INTELLINI GIANNI & C. | J11: 00593580673 | K11: 82604 | L11: TE | M11: 00593580673 | N11: PIAZZALE STAZIONE FF.SS. SNC | O11: 64026 | P11: ROSETO DEGLI ABRUZZI | R11: TE | S11: ABRUZZO | T11: Attiva | U11: SOCIETA' IN ACCOMANDITA SEMPLICE | V11: SOCIETA' DI PERSONE | X11: INTELLINI | Y11: GIANNI | Z11: M | AA11: 03/02/1973 | AB11: TE | AC11: ATRI | AD11: IT | AE11: 0 | AF11: VIA SAVINI 9 | AG11: 64026 | AH11: ROSETO DEGLI ABRUZZI | AI11: TE | AJ11: 0 | AK11: 0 | AL11: 0 | AM11: 0858992198 - 3287051039 GI | AN11: barstazi2@tiscali.it; | AO11: -
A12: 99005660 | B12: MASI CATERINA | C12: 00662080829 | D12: MSACRN44A60G543H | E12: VIA VIII MARZO 8 Piana degli Albanesi (PA), | F12: Y | H12: ITE5060203S0001 | I12: MASI CATERINA | J12: 00662080829 | K12: 193675 | L12: PA | M12: MSACRN44A60G543H | N12: VIALE VIII MARZO 19/21 | O12: 90037 | P12: PIANA DEGLI ALBANESI | R12: PA | S12: SICILIA | T12: Attiva | U12: IMPRESA INDIVIDUALE | V12: IMPRESE INDIVIDUALI | X12: MASI | Y12: CATERINA | Z12: F | AA12: 20/01/1944 | AB12: PA | AC12: PIANA DEGLI ALBANESI | AD12: IT | AE12: 0 | AF12: VIA SCHIADA' 17 | AG12: 90037 | AH12: PIANA DEGLI ALBANESI | AI12: PA | AJ12: 0 | AK12: 0 | AL12: 0 | AM12: 3283363212 - 0918930815 | AN12: caterina.masi@tiscali.it; dgiuseppe1979@libero.it | AO12: -
A13: 99014418 | B13: F.LLI IAPALUCCI S.N.C. DI IAPALUCCI MAURIZIO E IAPALUCCI MARIA GIUSEPPINA | C13: 00679950709 | D13: 00679950709 | E13: UMBERTO I - 86015 JELSI | F13: Y | H13: IT49800404S0001 | I13: F.LLI IAPALUCCI SNC DI IAPALUCCI MAURIZIO E IAPALUCCI MARIA GI USEPPINA | J13: 00679950709 | K13: 74452 | L13: CB | M13: 00679950709 | N13: PIAZZA UMBERTO I 22 | O13: 86015 | P13: JELSI | R13: CB | S13: MOLISE | T13: Attiva | U13: SOCIETA' IN NOME COLLETTIVO | V13: SOCIETA' DI PERSONE | X13: IAPALUCCI | Y13: MARIA GIUSEPPPINA | Z13: F | AA13: 11/07/1960 | AB13: CB | AC13: JELSI | AD13: IT | AE13: 0 | AF13: PIAZZA UMBERTO I 51 | AG13: 86015 | AH13: JELSI | AI13: CB | AJ13: 0 | AK13: 0 | AL13: IT | AM13: 0874710355 | AN13: iapalucci1986@gmail.com; | AO13: -
A14: 99000366 | B14: SCACCO NANDO | C14: 00712611003 | D14: SCCNND56L25L182N | E14: PIAZZALE MONSIGNOR GIUSEPPE CASC 15 - 00010 POLI RM | F14: Y | H14: ITB62C040CS0001 | I14: SCACCO NANDO | J14: 00712611003 | K14: 718153 | L14: RM | M14: SCCNND56L25L182N | N14: PIAZZA MONSIGNOR GIUSEPPE CASCIOLI 15 | O14: 00010 | P14: POLI | R14: RM | S14: LAZIO | T14: Attiva | U14: IMPRESA INDIVIDUALE | V14: IMPRESE INDIVIDUALI | X14: Scacco | Y14: Nando | Z14: M | AA14: 25/07/1956 | AB14: RM | AC14: TIVOLI | AD14: IT | AE14: 0 | AF14: VIA ROMA 25 | AG14: 00010 | AH14: POLI | AI14: RM | AJ14: 0 | AK14: 0 | AL14: 0 | AM14: 069551522 - 3387228585 | AN14: barfratelliscacco@gmail.com; | AO14: -
A15: 99000374 | B15: GAMBUTI ROMEO | C15: 00729120402 | D15: -- | E15: VIA RONCI 2 - 47833 MORCIANO DI ROMAGNA | F15: Y | H15: ITEAA80D0ES0001 | J15: 00729120402 | K15: 177058 | L15: RN | M15: GMBRMO43E22E278J | T15: Cessata favorevole | U15: IMPRESA INDIVIDUALE | V15: IMPRESE INDIVIDUALI | X15: - | Y15: - | Z15: - | AA15: - | AB15: - | AC15: - | AD15: - | AE15: - | AF15: - | AG15: - | AH15: - | AI15: - | AJ15: - | AK15: - | AL15: - | AM15: 0541989051 - 3920667006 | AN15: gabrielegambuti@virgilio.it; | AO15: -
A16: 99000387 | B16: PIETRINI UGO | C16: 00757420559 | D16: PTRGUO67T28L814H | E16: VIA CAPITONESE 9 - 05036 NARNI TR | F16: Y | H16: ITD98E0F0DS0001 | I16: PIETRINI UGO | J16: 00757420559 | K16: 78174 | L16: TR | M16: PTRGUO67T28L814H | N16: VIA CAPITONESE 9 | O16: 05035 | P16: NARNI | R16: TR | S16: UMBRIA | T16: Attiva | U16: IMPRESA INDIVIDUALE | V16: IMPRESE INDIVIDUALI | X16: PIETRINI | Y16: UGO | Z16: M | AA16: 28/12/1967 | AB16: VT | AC16: VETRALLA | AD16: IT | AE16: 0 | AF16: LOCALITA' VALLEANTICA SNC | AG16: 05029 | AH16: SAN GEMINI | AI16: TR | AJ16: 0 | AK16: 0 | AL16: IT | AM16: 0744751210 - 3478035369 | AN16: pietri14@ugopietrin.191.it; ugo.p@alice.it | AO16: -
A17: 99009470 | B17: BETTINI DI BETTINI MILENA E STUCCHI ROMANO & C. SNC | C17: 00864880968 | D17: 00864880968 | E17: VIA ROMA 21 - 20040 CAVENAGO DI BRIANZA MI | F17: Y | H17: IT8624000CS0001 | I17: BETTINI DI BETTINI MILENA E STUCCHI ROMANO & C. SNC | J17: 00864880968 | K17: 1169862 | L17: MB | M17: 07605360150 | N17: VIA ROMA 21 | O17: 20040 | P17: CAVENAGO DI BRIANZA | R17: MB | S17: LOMBARDIA | T17: Attiva | U17: SOCIETA' IN NOME COLLETTIVO | V17: SOCIETA' DI PERSONE | X17: BETTINI | Y17: MILENA | Z17: F | AA17: 17/02/1964 | AB17: MB | AC17: VIMERCATE | AD17: IT | AE17: 0 | AF17: VIA ALESSANDRO MANZONI 32 | AG17: 20873 | AH17: CAVENAGO DI BRIANZA | AI17: MB | AJ17: 0 | AK17: 0 | AL17: 0 | AM17: 029501460 | AN17: romano.stucchi@tiscali.it; | AO17: -
A18: 99014738 | B18: BAR PIZZERIA DI FALASCONI E ROSATI | C18: 00884570417 | D18: 00884570417 | E18: CORSO GIOVANNI XXIII 35 61026 PIANDIMELETO (PU) | F18: Y | H18: IT788B0A0ES0001 | I18: FALASCONI E ROSATI SNC | J18: 00884570417 | K18: 93409 | L18: PS | M18: 00884570417 | N18: CORSO GIOVANNI XXIII 35 | O18: 61026 | P18: PIANDIMELETO | R18: PU | S18: MARCHE | T18: Attiva | U18: SOCIETA' IN NOME COLLETTIVO | V18: SOCIETA' DI PERSONE | X18: FALASCONI | Y18: ANTONIO | Z18: M | AA18: 22/12/1961 | AB18: PU | AC18: APECCHIO | AD18: IT | AE18: 0 | AF18: VIA SANT' ANTONIO 46 | AG18: 61026 | AH18: PIANDIMELETO | AI18: PU | AJ18: CASE SPARSE | AK18: 0 | AL18: IT | AM18: - | AN18: ROSALIAROSALIA381@GMAIL.COM; | AO18: -
A19: 99004421 | B19: MANUSHIDI PARADISO LOREDANA | C19: 00887590628 | D19: PRDLDN60L50G631D | E19: PIAZZA S.S. ANNUNZIATA 16 - 82020 PIETRELCINA BN | F19: Y | H19: IT4C07090FS0001 | I19: MANUSHI DI PARADISO LOREDANA | J19: 00887590628 | K19: 69417 | L19: BN | M19: PRDLDN60L50G631D | N19: PIAZZA SANTISSIMA ANNUNZIATA 16 | O19: 82020 | P19: PIETRELCINA | R19: BN | S19: CAMPANIA | T19: Attiva | U19: IMPRESA INDIVIDUALE | V19: IMPRESE INDIVIDUALI | X19: PARADISO | Y19: LOREDANA | Z19: F | AA19: 10/07/1960 | AB19: BN | AC19: PIETRELCINA | AD19: IT | AE19: 0 | AF19: 0 | AG19: 82020 | AH19: PIETRELCINA | AI19: BN | AJ19: 0 | AK19: 0 | AL19: 0 | AM19: 0824991031 - 3475933994 | AN19: lparadiso60@gmail.com; | AO19: -
A20: 99013429 | B20: LAGROTTERIA MARIA ANTONIETTA | C20: 00930240791 | D20: LGRMNT62R67F537Z | E20: VIA N.A.SILVAGGIO SNC, 89843, MAIERATO (VV) | F20: Y | H20: IT77450A0AS0001 | I20: LAGROTTERIA MARIA ANTONIETTA | J20: 00930240791 | K20: 144497 | L20: VV | M20: LGRMNT62R67F537Z | N20: VIA N.A.SILVAGGIO SNC | O20: 89843 | P20: MAIERATO | R20: VV | S20: CALABRIA | T20: Attiva | U20: IMPRESA INDIVIDUALE | V20: IMPRESE INDIVIDUALI | X20: LAGROTTERIA | Y20: MARIA ANTONIETTA | Z20: F | AA20: 27/10/1962 | AB20: VV | AC20: VIBO VALENTIA | AD20: IT | AE20: 0 | AF20: VIA MARTELLITO SNC | AG20: 89843 | AH20: MAIERATO | AI20: VV | AJ20: 0 | AK20: 0 | AL20: 0 | AM20: - | AN20: tabacchi.lagrotteria@gmail.com; | AO20: -
A21: 99013876 | B21: LA GARUFFA DI WU XIAOE | C21: 00950430140 | D21: WUXXIA83R50Z210V | E21: NAZIONALE - 23013 COSIO VALTELLINO | F21: Y | H21: ITEDE50201S0001 | I21: BAR LA GARUFFA DI WU XIAOE | J21: 00950430140 | K21: 72172 | L21: SO | M21: WUXXIA83R50Z210V | N21: VIA STATALE 57 | O21: 23013 | P21: COSIO VALTELLINO | R21: SO | S21: LOMBARDIA | T21: Attiva | U21: IMPRESA INDIVIDUALE | V21: IMPRESE INDIVIDUALI | X21: WU | Y21: XIAOE | Z21: F | AA21: 10/10/1983 | AB21: E | AC21: CINA | AD21: CN | AE21: CINA | AF21: VIA ROMA 45 | AG21: 23013 | AH21: COSIO VALTELLINO | AI21: SO | AJ21: 0 | AK21: 0 | AL21: IT | AM21: 3883410286 - 3319794575 | AN21: haoxin.mercatone@hotmail.it; | AO21: -
A22: 99013286 | B22: BIANCHINI CESARE | C22: 00952320141 | D22: BNCCSR72R21A787Q | E22: VIA V ALPINI 151, 23017, MORBEGNO (SO) | F22: Y | H22: IT61E50206S0001 | I22: BIANCHINI CESARE | J22: 00952320141 | K22: 71774 | L22: SO | M22: BNCCSR72R21A787Q | N22: VIA V ALPINI 132 | O22: 23017 | P22: MORBEGNO | R22: SO | S22: LOMBARDIA | T22: Attiva | U22: IMPRESA INDIVIDUALE | V22: IMPRESE INDIVIDUALI | X22: BIANCHINI | Y22: CESARE | Z22: M | AA22: 21/10/1972 | AB22: SO | AC22: BERBENNO DI VALTELLINA | AD22: IT | AE22: 0 | AF22: VIA CARLO FABANI 18 | AG22: 23017 | AH22: MORBEGNO | AI22: SO | AJ22: 0 | AK22: 0 | AL22: IT | AM22: 0342614618 - 3479002454 | AN22: bianchini.cesare@gmail.com; | AO22: -
A23: 99013644 | B23: CAPURSO GIOVANNI | C23: 00969410588 | D23: CPRGNN48B22A883V | E23: ROSSINI CARLO CONTI - 00147 ROMA | F23: Y | H23: IT64230502S0001 | I23: CAPURSO GIOVANNI | J23: 00969410588 | K23: 339901 | L23: RM | M23: CPRGNN48B22A883V | N23: VIA CARLO CONTI ROSSINI 9/11 | O23: 00147 | P23: ROMA | R23: RM | S23: LAZIO | T23: Attiva | U23: IMPRESA INDIVIDUALE | V23: IMPRESE INDIVIDUALI | X23: CAPURSO | Y23: GIOVANNI | Z23: M | AA23: 22/02/1948 | AB23: BT | AC23: BISCEGLIE | AD23: IT | AE23: 0 | AF23: VIA CARLO CONTI ROSSINI 26 | AG23: 00147 | AH23: ROMA | AI23: RM | AJ23: 0 | AK23: 0 | AL23: IT | AM23: 0651606306 - 3383609906 | AN23: giovanni.capurso48@gmail.com; | AO23: -
A24: 99014524 | B24: DI FRANCO MIRCO | C24: 00974350944 | D24: DFRMRC92H19C096B | E24: DELLA REPUBBLICA - 86087 RIONERO SANNITICO | F24: Y | H24: IT7C500909S0001 | I24: DI FRANCO MIRCO | J24: 00974350944 | K24: 208314 | L24: IS | M24: DFRMRC92H19C096B | N24: PIAZZA DELLA REPUBBLICA SNC | O24: 86087 | P24: RIONERO SANNITICO | R24: IS | S24: MOLISE | T24: Attiva | U24: IMPRESA INDIVIDUALE | V24: IMPRESE INDIVIDUALI | X24: DI FRANCO | Y24: MIRCO | Z24: M | AA24: 19/06/1992 | AB24: AQ | AC24: CASTEL DI SANGRO | AD24: 0 | AE24: 0 | AF24: CONTRADA MONTALTO 3 | AG24: 86087 | AH24: RIONERO SANNITICO | AI24: IS | AJ24: 0 | AK24: 0 | AL24: IT | AM24: +39 334 830 1760 | AN24: difrancomirco1992@gmail.com; | AO24: -
A25: 99000551 | B25: BAR TABACCHI DI TARANTINI ANTONIO | C25: 00984250159 | D25: TRNNTN41H30L328F | E25: VIA DEI CINQUECENTO 22 - 20139 MILANO MI | F25: Y | H25: ITE48D0900S0001 | I25: TARANTINI ANTONIO | J25: 00984250159 | K25: 821566 | L25: MI | M25: TRNNTN41H30L328F | N25: VIA DEI CINQUECENTO 0025 | O25: 20139 | P25: MILANO | R25: MI | S25: LOMBARDIA | T25: Attiva | U25: IMPRESA INDIVIDUALE | V25: IMPRESE INDIVIDUALI | X25: TARANTINI | Y25: ANTONIO | Z25: M | AA25: 30/06/1941 | AB25: BT | AC25: TRANI | AD25: IT | AE25: 0 | AF25: VIA DEI CINQUECENTO 0025 | AG25: 20139 | AH25: MILANO | AI25: MI | AJ25: 0 | AK25: 0 | AL25: IT | AM25: 0255212400 - 3477788766 | AN25: domenicotarantina@tiscali.it; domenicotarantini@tiscali.it | AO25: -
A26: 99000577 | B26: DELLE VERGINI BERNARDO | C26: 01026680718 | D26: DLLBNR61H19I072G | E26: VIA XX SETTEMBRE 7 - 71010 SAN PAOLO DI CIVITATE FG | F26: Y | H26: ITA98C0A02S0001 | I26: DELLE VERGINI BERNARDO | J26: 01026680718 | K26: 128770 | L26: FG | M26: DLLBNR61H19I072G | N26: VIA XX SETTEMBRE 7/9 | O26: 71010 | P26: SAN PAOLO DI CIVITATE | R26: FG | S26: PUGLIA | T26: Attiva | U26: IMPRESA INDIVIDUALE | V26: IMPRESE INDIVIDUALI | X26: DELLE VERGINI | Y26: BERNARDO NATALE | Z26: M | AA26: 19/06/1961 | AB26: FG | AC26: SAN PAOLO DI CIVITATE | AD26: IT | AE26: 0 | AF26: VIA LEOPARDI | AG26: 71010 | AH26: SAN PAOLO DI CIVITATE | AI26: FG | AJ26: 0 | AK26: 0 | AL26: 0 | AM26: 0882552364 - 3479379290 | AN26: barbernardo@libero.it; | AO26: -
A27: 99009296 | B27: ARTE TIPOGRAFICA DI ZAGARESE ANGELO | C27: 01055660623 | D27: ZGRNGL67S27A783F | E27: VIA P. COLUMBRO ZONA S.COLOMBA - 82100 BENEVENTO BN | F27: Y | H27: ITEF810006S0001 | I27: ARTE TIPOGRAFICA DI ZAGARESE ANGELO | J27: 01055660623 | K27: 77480 | L27: BN | M27: ZGRNGL67S27A783F | N27: VIA P. COLUMBRO ZONA S.COLOMBA | O27: 82100 | P27: BENEVENTO | R27: BN | S27: CAMPANIA | T27: Attiva | U27: IMPRESA INDIVIDUALE | V27: IMPRESE INDIVIDUALI | X27: ZAGARESE | Y27: ANGELO | Z27: M | AA27: 27/11/1967 | AB27: BN | AC27: BENEVENTO | AD27: IT | AE27: 0 | AF27: VIA DUCA D' AOSTA 6 | AG27: 82100 | AH27: BENEVENTO | AI27: BN | AJ27: 0 | AK27: 0 | AL27: 0 | AM27: 0824363392 - 3280237216 | AN27: tabax@libero.it; | AO27: -
A28: 99013491 | B28: VERDE MARIA ROSARIA | C28: 01067450617 | D28: VRDMRS60E54C561B | E28: VIA UMBERTO I 56, 81030, CESA (CE) | F28: Y | H28: ITF3A7010BS0001 | J28: 01067450617 | K28: 99680 | L28: CE | M28: VRDMRS60E54C561B | T28: Cessata favorevole | U28: IMPRESA INDIVIDUALE | V28: IMPRESE INDIVIDUALI | X28: - | Y28: - | Z28: - | AA28: - | AB28: - | AC28: - | AD28: - | AE28: - | AF28: - | AG28: - | AH28: - | AI28: - | AJ28: - | AK28: - | AL28: - | AM28: 0815021650 - 3891225553 | AN28: giulio.parisini@hotmail.it; | AO28: -
A29: 99013460 | B29: GUIDI ELENA | C29: 01097530503 | D29: GDULNE61E69G702T | E29: VIA NAZARIO SAURO 183, 56021, CASCINA (PI) | F29: Y | H29: IT8F820601S0001 | I29: GUIDI ELENA | J29: 01097530503 | K29: 100919 | L29: PI | M29: GDULNE61E69G702T | N29: VIA NAZARIO SAURO 183 | O29: 56021 | P29: CASCINA | Q29: LATIGNANO | R29: PI | S29: TOSCANA | T29: Attiva | U29: IMPRESA INDIVIDUALE | V29: IMPRESE INDIVIDUALI | X29: GUIDI | Y29: ELENA | Z29: F | AA29: 29/05/1961 | AB29: PI | AC29: PISA | AD29: IT | AE29: 0 | AF29: VIA ROTINA 163 | AG29: 56021 | AH29: CASCINA | AI29: PI | AJ29: LATIGNANO | AK29: 0 | AL29: 0 | AM29: 050780452 - 3470363324 | AN29: francescomartinelli88@gmail.com; | AO29: -
A30: 99014789 | B30: BAR TABACCHI DA ANTONIETTA DI FILIPPONI MATTEO | C30: 01147060576 | D30: FLPMTT88L13H282G | E30: PONTE CRISPOLTI - 02010 RIVODUTRI | F30: Y | H30: ITA71C030BS0001 | I30: BAR TABACCHI DA ANTONIETTA DI FILIPPONI MATTEO | J30: 01147060576 | K30: 71689 | L30: RI | M30: FLPMTT88L13H282G | N30: LOCALITA' PONTE CRISPOLTI 6 | O30: 02010 | P30: RIVODUTRI | R30: RI | S30: LAZIO | T30: Attiva | U30: IMPRESA INDIVIDUALE | V30: IMPRESE INDIVIDUALI | X30: FILIPPONI | Y30: MATTEO | Z30: M | AA30: 13/07/1988 | AB30: RI | AC30: RIETI | AD30: IT | AE30: 0 | AF30: LOCALITA' PONTE CRISPOLTI 7 | AG30: 02010 | AH30: RIVODUTRI | AI30: RI | AJ30: 0 | AK30: 0 | AL30: IT | AM30: 328-5463547 | AN30: MATTOFILLO@GMAIL.COM; | AO30: -
A31: 99008509 | B31: BAR GELATERIA CREPERIA CAPRICE 2 DI BERNACCA MATTEO & C. SNC | C31: 01164970459 | D31: 01164970459 | E31: VIA CARDUCCI GIOSUE' 3, 54033, CARRARA (MS) | F31: Y | H31: IT8068080DS0001 | I31: BAR GELATERIA CREPERIA CAPRICE 2 DI BERNACCA MATTEO & C. SNC | J31: 01164970459 | K31: 118323 | L31: MS | M31: 01164970459 | N31: VIA CARDUCCI GIOSUE' 3 | O31: 54033 | P31: CARRARA | R31: MS | S31: TOSCANA | T31: Attiva | U31: SOCIETA' IN NOME COLLETTIVO | V31: SOCIETA' DI PERSONE | X31: MURACCHIOLI | Y31: ARIANNA | Z31: F | AA31: 08/07/1982 | AB31: MS | AC31: MASSA | AD31: IT | AE31: 0 | AF31: VIA CASTAGNOLA DI SOTTO 65 | AG31: 54100 | AH31: MASSA | AI31: MS | AJ31: 0 | AK31: 0 | AL31: IT | AM31: 0585846163 - 3476100512 | AN31: aryanna221@yahoo.it; | AO31: -
A32: 99013180 | B32: LUIGI E DAIGORO S.R.L.S. | C32: 01170840571 | D32: 01170840571 | E32: VIA SANDRO PERTINI 211 - 02100 RIETI | F32: Y | H32: IT9E950A0BS0001 | I32: LUIGI E DAIGORO S.R.L.S. | J32: 01170840571 | K32: 73387 | L32: RI | M32: 01170840571 | N32: VIA SANDRO PERTINI 211 | O32: 02100 | P32: RIETI | R32: RI | S32: LAZIO | T32: Attiva | U32: SOCIETA' A RESPONSABILITA' LIMITATA SEMPLIFICATA | V32: SOCIETA' DI CAPITALE | X32: CELLI | Y32: MARIA LUIGIA | Z32: F | AA32: 20/06/1958 | AB32: RI | AC32: RIETI | AD32: 0 | AE32: 0 | AF32: VIA SALARIA PER L'AQUILA 41 | AG32: 02100 | AH32: RIETI | AI32: RI | AJ32: 0 | AK32: 0 | AL32: IT | AM32: 3917154863 - 3927121987 | AN32: luigiedaigorosrls@gmail.com; | AO32: -
A33: 99013472 | B33: IL TABACCHINO DI EMANUELA DAL FERRO | C33: 01186460950 | D33: DLFMNL76L45E591O | E33: CORSO CATTEDRALE 56, 09091, ALES (OR) | F33: Y | H33: IT8A1D080CS0001 | I33: IL TABACCHINO DI EMANUELA DAL FERRO | J33: 01186460950 | K33: 137269 | L33: OR | M33: DLFMNL76L45E591O | N33: CORSO CATTEDRALE 56 | O33: 09091 | P33: ALES | R33: OR | S33: SARDEGNA | T33: Attiva | U33: IMPRESA INDIVIDUALE | V33: IMPRESE INDIVIDUALI | X33: DAL FERRO | Y33: EMANUELA | Z33: F | AA33: 05/07/1976 | AB33: MI | AC33: LIMBIATE | AD33: IT | AE33: 0 | AF33: VIA IV NOVEMBRE 48 | AG33: 09091 | AH33: ALES | AI33: OR | AJ33: 0 | AK33: 0 | AL33: IT | AM33: 0783998852 - 3452448186 | AN33: iltabacchinoales@gmail.com; | AO33: -
A34: 99006385 | B34: CAFFE' LIDIA SNCDEI FRATELLI CERBINO | C34: 01192620761 | D34: 01192620761 | E34: PIAZZA VITTORIO EMANUELE 12 - 85048 ROTONDA PZ | F34: Y | H34: IT560D0C0DS0001 | I34: CAFFE' LIDIA SNC DEI FRATELLI CERBINO | J34: 01192620761 | K34: 83902 | L34: PZ | M34: 01192620761 | N34: PIAZZA VITTORIO EMANUELE 12 | O34: 85048 | P34: ROTONDA | R34: PZ | S34: BASILICATA | T34: Attiva | U34: SOCIETA' IN NOME COLLETTIVO | V34: SOCIETA' DI PERSONE | X34: CERBINO | Y34: FRANCESCO | Z34: M | AA34: 20/05/1960 | AB34: PZ | AC34: ROTONDA | AD34: IT | AE34: 0 | AF34: VIA ALDO MORO 3 | AG34: 85048 | AH34: ROTONDA | AI34: PZ | AJ34: 0 | AK34: 0 | AL34: 0 | AM34: 0973661171 | AN34: antoniocerbino9@gmail.com; antoniocervino9@gmail.com | AO34: -
A35: 99000737 | B35: D'ANGELO ROBERTO | C35: 01198750448 | D35: DNGRRT65S19H769C | E35: VIA GALILEO GALILEI 1 - 63066 GROTTAMMARE AP | F35: Y | H35: IT9F8B0A0BS0001 | I35: D'ANGELO ROBERTO | J35: 01198750448 | K35: 120626 | L35: AP | M35: DNGRRT65S19H769C | N35: VIA GALILEO GALILEI 1 | O35: 63066 | P35: GROTTAMMARE | R35: AP | S35: MARCHE | T35: Attiva | U35: IMPRESA INDIVIDUALE | V35: IMPRESE INDIVIDUALI | X35: D'ANGELO | Y35: ROBERTO | Z35: M | AA35: 19/11/1965 | AB35: AP | AC35: SAN BENEDETTO DEL TRONTO | AD35: IT | AE35: 0 | AF35: VIA GIAN LORENZO BERNINI 86 | AG35: 63066 | AH35: GROTTAMMARE | AI35: AP | AJ35: 0 | AK35: 0 | AL35: IT | AM35: 0735736064 | AN35: taroda65@gmail.com; | AO35: -
A36: 99000740 | B36: BAR COMMERCIO DI ROGNONI R. | C36: 01203900186 | D36: RGNRRT67R30G388W | E36: PIAZZA BONACCOSA 10 - 27020 DORNO PV | F36: Y | H36: IT564B040ES0001 | I36: ROGNONI ROBERTO | J36: 01203900186 | K36: 172994 | L36: PV | M36: RGNRRT67R30G388W | N36: PIAZZA BONACOSSA 10 | O36: 27020 | P36: DORNO | R36: PV | S36: LOMBARDIA | T36: Attiva | U36: IMPRESA INDIVIDUALE | V36: IMPRESE INDIVIDUALI | X36: ROGNONI | Y36: ROBERTO | Z36: M | AA36: 30/10/1967 | AB36: PV | AC36: PAVIA | AD36: IT | AE36: 0 | AF36: 0 | AG36: 0 | AH36: 0 | AI36: 0 | AJ36: 0 | AK36: 0 | AL36: 0 | AM36: 038284028 | AN36: simobibo@libero.it; | AO36: -
A37: 99009572 | B37: CANTONI DA.RO. SRL | C37: 01211820160 | D37: 01211820160 | E37: VIA I MAGGIO 2/4 - 24060 GORLAGO BG | F37: Y | H37: ITF2840402S0001 | I37: CANTONI DA.RO. SRL | J37: 01211820160 | K37: 193775 | L37: BG | M37: 01211820160 | N37: VIA I MAGGIO 2/4 | O37: 24060 | P37: GORLAGO | R37: BG | S37: LOMBARDIA | T37: Attiva | U37: SOCIETA' A RESPONSABILITA' LIMITATA | V37: SOCIETA' DI CAPITALE | X37: CANTONI | Y37: ROBERTO | Z37: M | AA37: 23/01/1972 | AB37: BG | AC37: TRESCORE BALNEARIO | AD37: IT | AE37: 0 | AF37: VIA GUGLIELMO MARCONI 34 | AG37: 24060 | AH37: CAROBBIO DEGLI ANGELI | AI37: BG | AJ37: 0 | AK37: 0 | AL37: IT | AM37: 035951037 - 3456987138 | AN37: roberto_cantoni@virgilio.it; roberto@bowlinggorlago.com | AO37: -
A38: 99004361 | B38: TABACCHERIA RIV. N. 3DI MOSCA NADIA | C38: 01212310088 | D38: MSCNDA64H62F704J | E38: VIA ROMA 3 - 18012 BORDIGHERA IM | F38: Y | H38: IT990B060DS0001 | I38: MOSCA NADIA | J38: 01212310088 | K38: 107871 | L38: IM | M38: MSCNDA64H62F704J | N38: VIA ROMA 3 | O38: 18012 | P38: BORDIGHERA | R38: IM | S38: LIGURIA | T38: Attiva | U38: IMPRESA INDIVIDUALE | V38: IMPRESE INDIVIDUALI | X38: MOSCA | Y38: NADIA | Z38: F | AA38: 22/06/1964 | AB38: MB | AC38: MONZA | AD38: IT | AE38: 0 | AF38: VIA CESARE BALBO 1 | AG38: 18012 | AH38: BORDIGHERA | AI38: IM | AJ38: 0 | AK38: 0 | AL38: 0 | AM38: 0184260783 - 3926967366 | AN38: tnsf@libero.it; | AO38: -
A39: 99008458 | B39: BAR MADISON DI GUASCONI FEDERICA | C39: 01226030334 | D39: GSCFRC65R63G535Z | E39: VIA EMANUELLI ANGOLO VIA PUCCINI 54 - 29121 PIACENZA PC | F39: Y | H39: ITAD89090ES0001 | I39: BAR MADISON DI GUASCONI FEDERICA | J39: 01226030334 | K39: 144086 | L39: PC | M39: GSCFRC65R63G535Z | N39: VIA EMANUELLI ANGOLO VIA PUCCINI 54 | O39: 29100 | P39: PIACENZA | R39: PC | S39: EMILIA-ROMAGNA | T39: Attiva | U39: IMPRESA INDIVIDUALE | V39: IMPRESE INDIVIDUALI | X39: GUASCONI | Y39: FEDERICA | Z39: F | AA39: 23/10/1965 | AB39: PC | AC39: PIACENZA | AD39: IT | AE39: 0 | AF39: VIA AMILCARE PONCHIELLI 15 | AG39: 29121 | AH39: PIACENZA | AI39: PC | AJ39: 0 | AK39: 0 | AL39: 0 | AM39: 366 6614314 | AN39: bar.madison@libero.it; | AO39: -
A40: 99000777 | B40: TREOSSI FRANCESCA | C40: 01235690391 | D40: TRSFNC72C41H199F | E40: VIA DISMANO 621 - 48100 RAVENNA RA | F40: Y | H40: IT4E490E0ES0001 | I40: TREOSSI FRANCESCA | J40: 01235690391 | K40: 172479 | L40: RA | M40: TRSFNC72C41H199F | N40: VIA DISMANO 621 | O40: 48125 | P40: RAVENNA | Q40: SAN ZACCARIA | R40: RA | S40: EMILIA-ROMAGNA | T40: Attiva | U40: IMPRESA INDIVIDUALE | V40: IMPRESE INDIVIDUALI | X40: TREOSSI | Y40: FRANCESCA | Z40: F | AA40: 01/03/1972 | AB40: RA | AC40: RAVENNA | AD40: IT | AE40: 0 | AF40: VIA MALVA NORD 61 | AG40: 48015 | AH40: CERVIA | AI40: RA | AJ40: 0 | AK40: 0 | AL40: IT | AM40: 0544564856 - 3356040141 | AN40: caffetteria2005@hotmail.it; | AO40: -
...

Sheet LegaliRappresentanti
A1: Codice Fiscale Esponente | B1: ﻿Crif Number | C1: Cognome Esponente | D1: Nome Esponente | E1: Sesso | F1: Data di nascita | G1: Provincia di Nascita | H1: Comune di Nascita | I1: Nazione di Nascita | J1: Cittadinanza | K1: Indirizzo | L1: CAP | M1: Comune | N1: Provincia | O1: Frazione | P1: Altre indicazioni | Q1: Nazione | R1: Telefono | S1: Email | T1: PEC
A2: PSQSLV99L53I403K | B2: IT000B080FS0001 | C2: PASQUAL | D2: SILVIA | E2: F | F2: 13/07/1999 | G2: PN | H2: SAN VITO AL TAGLIAMENTO | K2: VIA ALDO MORO 25 | L2: 33076 | M2: PRAVISDOMINI | N2: PN | Q2: IT | R2: - | S2: - | T2: - | U2: =VLOOKUP(A:A,'Imprese_File completo'!M:M,1,FALSE) -> #N/A
A3: PLMNLT71M58A285Y | B3: IT0016070ES0001 | C3: PALUMBO | D3: NICOLETTA | E3: F | F3: 18/08/1971 | G3: BA | H3: ANDRIA | I3: IT | K3: VIA ALESSANDRO MANZONI 12 | L3: 76123 | M3: ANDRIA | N3: BT | Q3: IT | R3: 3464047598 | S3: riki.vitale@gmail.com; | T3: snai.palumbo@pec.it | U3: =VLOOKUP(A:A,'Imprese_File completo'!M:M,1,FALSE) -> PLMNLT71M58A285Y
A4: LSCNTN73T08Z133Z | B4: IT00410605S0001 | C4: LA SCALIA | D4: ANTONIO | E4: M | F4: 08/12/1973 | G4: E | H4: SVIZZERA | I4: CH | J4: ITALIA | K4: VIA OSSOLA 5 | L4: 92024 | M4: CANICATTI' | N4: AG | Q4: IT | R4: - | S4: - | T4: - | U4: =VLOOKUP(A:A,'Imprese_File completo'!M:M,1,FALSE) -> #N/A
A5: PTRCGR73E07B602B | B5: IT00410605S0001 | C5: PITRUZZELLA | D5: CALOGERO | E5: M | F5: 07/05/1973 | G5: AG | H5: CANICATTI' | I5: IT | K5: CONTRADA FABRIZIO SNC | L5: 92024 | M5: CANICATTI' | N5: AG | Q5: IT | R5: - | S5: - | T5: - | U5: =VLOOKUP(A:A,'Imprese_File completo'!M:M,1,FALSE) -> #N/A
A6: WNGDYA97R28Z210K | B6: IT005C0E0BS0001 | C6: WANG | D6: DAYU | E6: M | F6: 28/10/1997 | G6: E | H6: CINA | I6: CN | J6: CINA | K6: VIA VITTORIO VENETO 156 | L6: 52100 | M6: AREZZO | N6: AR | Q6: IT | R6: - | S6: - | T6: - | U6: =VLOOKUP(A:A,'Imprese_File completo'!M:M,1,FALSE) -> #N/A
A7: PMPFNC78D66F870A | B7: IT01120C04S0001 | C7: POMPEI | D7: FRANCESCA | E7: F | F7: 26/04/1978 | G7: TE | H7: NERETO | I7: IT | K7: VIA ANTONIO CANOVA 9 | L7: 64016 | M7: SANT'EGIDIO ALLA VIBRATA | N7: TE | Q7: IT | R7: 3935513952 | S7: pompeifrancesca@alice.it; | T7: - | U7: =VLOOKUP(A:A,'Imprese_File completo'!M:M,1,FALSE) -> PMPFNC78D66F870A
A8: SLAGNN68H23C783Q | B8: IT01140F07S0001 | C8: SAULI | D8: GIOVANNI MARIA | E8: M | F8: 23/06/1968 | G8: AQ | H8: CIVITELLA ROVETO | I8: IT | K8: VIA DELLE ROSE 1 | L8: 67054 | M8: CIVITELLA ROVETO | N8: AQ | Q8: IT | R8: - | S8: - | T8: - | U8: =VLOOKUP(A:A,'Imprese_File completo'!M:M,1,FALSE) -> #N/A
A9: SSSLPN67S66H264V | B9: IT01190703S0001 | C9: SASSONE | D9: LIDIA PINA | E9: F | F9: 26/11/1967 | G9: MI | H9: RHO | I9: IT | K9: CORSO GARIBALDI 107 | L9: 85038 | M9: SENISE | N9: PZ | Q9: IT | R9: - | S9: - | T9: - | U9: =VLOOKUP(A:A,'Imprese_File completo'!M:M,1,FALSE) -> #N/A
A10: CNIMCN75L31G273R | B10: IT011D020DS0001 | C10: IACONA | D10: MARCANTONIO | E10: M | F10: 31/07/1975 | G10: PA | H10: PALERMO | I10: IT | K10: VIA CAPPUCCINI 317 | L10: 90129 | M10: PALERMO | N10: PA | Q10: IT | R10: 091-6166979 - 320-0746369 | S10: snaimendola58@libero.it; | T10: iaconamarcantonio@pec.confcommercio.pa.it | U10: =VLOOKUP(A:A,'Imprese_File completo'!M:M,1,FALSE) -> CNIMCN75L31G273R
A11: CSNCRN87A68D122Y | B11: IT015C010BS0001 | C11: COSENTINO | D11: CATERINA | E11: F | F11: 28/01/1987 | G11: KR | H11: CROTONE | I11: IT | K11: VIA RIALTO 47 | L11: 35020 | M11: BRUGINE | N11: PD | Q11: IT | R11: - | S11: - | T11: - | U11: =VLOOKUP(A:A,'Imprese_File completo'!M:M,1,FALSE) -> #N/A
A12: XIALGL90A48Z210S | B12: IT015C0D0AS0001 | C12: XIA | D12: LINGLING | E12: F | F12: 08/01/1990 | G12: E | H12: CINA | I12: CN | J12: CINA | K12: VIA SANT'ANTONIO 26 | L12: 55049 | M12: VIAREGGIO | N12: LU | Q12: IT | R12: - | S12: - | T12: - | U12: =VLOOKUP(A:A,'Imprese_File completo'!M:M,1,FALSE) -> #N/A
A13: HUXYNU87A05Z210Q | B13: IT01940104S0001 | C13: HU | D13: YUNAO | E13: M | F13: 05/01/1987 | G13: E | H13: ZHEJIANG | I13: CN | J13: CINA | K13: VIA NAZARIO SAURO 12 | L13: 21010 | M13: BESNATE | N13: VA | Q13: IT | R13: - | S13: - | T13: - | U13: =VLOOKUP(A:A,'Imprese_File completo'!M:M,1,FALSE) -> #N/A
A14: TRVNNA60P41F646F | B14: IT01980800S0001 | C14: TRAVAGLINI | D14: ANNA | E14: F | F14: 01/09/1960 | G14: PE | H14: MONTESILVANO | K14: VIA VESTINA 507 | L14: 65015 | M14: MONTESILVANO | N14: PE | Q14: IT | R14: 0854452071 | S14: anna.travaglini60@gmail.com; | T14: - | U14: =VLOOKUP(A:A,'Imprese_File completo'!M:M,1,FALSE) -> TRVNNA60P41F646F
A15: HUXRLU89M51Z210E | B15: IT01A30107S0001 | C15: HU | D15: RULU | E15: F | F15: 11/08/1989 | G15: E | H15: CINA | I15: CN | J15: ITALIA | K15: VIALE TRIVULZIO 3/A | L15: 26845 | M15: CODOGNO | N15: LO | R15: 0377437003 - 3201727118 | S15: rulu1@live.it; | T15: 0021986460001@POSTACERTIFICATA.TABACCAI.IT | U15: =VLOOKUP(A:A,'Imprese_File completo'!M:M,1,FALSE) -> HUXRLU89M51Z210E
A16: MRNMRK92R14H501Q | B16: IT02510C0DS0001 | C16: MARIANI | D16: MIRKO | E16: M | F16: 14/10/1992 | G16: RM | H16: ROMA | K16: VIA LAURENTINA 193 | L16: 00142 | M16: ROMA | N16: RM | P16: SCALA U P. T INT. 2 | Q16: IT | R16: - | S16: - | T16: - | U16: =VLOOKUP(A:A,'Imprese_File completo'!M:M,1,FALSE) -> #N/A
A17: SVRNLT78P46Z129Q | B17: IT02590B04S0001 | C17: SEVERIN | D17: NICOLETA | E17: F | F17: 06/09/1978 | G17: E | H17: ROMANIA | I17: RO | J17: ITALIA | K17: VIA LARIO 5 | L17: 20159 | M17: MILANO | N17: MI | Q17: IT | R17: - | S17: - | T17: - | U17: =VLOOKUP(A:A,'Imprese_File completo'!M:M,1,FALSE) -> #N/A
A18: NTLSFN73D14H501O | B18: IT026A0507S0001 | C18: NATILI | D18: STEFANO | E18: M | F18: 14/04/1973 | G18: RM | H18: ROMA | I18: IT | K18: VIA AUGUSTO CASCIANI 21/A | L18: 00133 | M18: ROMA | N18: RM | R18: 062051691 | S18: - | T18: stefanonatili@pec.it | U18: =VLOOKUP(A:A,'Imprese_File completo'!M:M,1,FALSE) -> NTLSFN73D14H501O
A19: MGGMRA79B14D643U | B19: IT029F0D0AS0001 | C19: MAGGIO | D19: MARIO | E19: M | F19: 14/02/1979 | G19: FG | H19: FOGGIA | K19: PIAZZA NUOVA 17 | L19: 71121 | M19: FOGGIA | N19: FG | Q19: IT | R19: - | S19: - | T19: - | U19: =VLOOKUP(A:A,'Imprese_File completo'!M:M,1,FALSE) -> #N/A
A20: DPENRN82B18F158F | B20: IT02DA0501S0001 | C20: DEPU | D20: ANDREA ANGELO | E20: M | F20: 18/02/1982 | G20: ME | H20: MESSINA | I20: IT | K20: TRAVERSA A DI VIA GAETANO MARTINO 2 | L20: 98039 | M20: TAORMINA | N20: ME | Q20: IT | R20: 3407516929 | S20: andrea.depu@icloud.com; | T20: - | U20: =VLOOKUP(A:A,'Imprese_File completo'!M:M,1,FALSE) -> DPENRN82B18F158F
A21: LNEGRL82H51G273P | B21: IT02E3060DS0001 | C21: LEONE | D21: GABRIELLA GIUSEPPINA | E21: F | F21: 11/06/1982 | G21: PA | H21: PALERMO | I21: IT | K21: VIA GUGLIELMO ALBIMONTE 43 | L21: 90138 | M21: PALERMO | N21: PA | Q21: IT | R21: - | S21: - | T21: - | U21: =VLOOKUP(A:A,'Imprese_File completo'!M:M,1,FALSE) -> #N/A
A22: GRNLCU85B21H490K | B22: IT02E40508S0001 | C22: GRANDINETTI | D22: LUCA | E22: M | F22: 21/02/1985 | G22: CS | H22: ROGLIANO | I22: IT | K22: VIA GUGLIELMO TADDEI 4 | L22: 56124 | M22: PISA | N22: PI | Q22: IT | R22: 3408401653 - 050544511 | S22: lucagrandinetti5@virgilio.it; | T22: tabacchidilucagrandinetti@pec.it | U22: =VLOOKUP(A:A,'Imprese_File completo'!M:M,1,FALSE) -> GRNLCU85B21H490K
A23: NGLCLD68M09H501R | B23: IT031B060ES0001 | C23: ANGELETTI | D23: CLAUDIO | E23: M | F23: 09/08/1968 | G23: RM | H23: ROMA | I23: IT | K23: VIA GIUSEPPE GARIBALDI 10 | L23: 00010 | M23: MONTORIO ROMANO | N23: RM | Q23: IT | R23: 077462216 - 3487423110 | S23: klaudium@tiscali.it; | T23: - | U23: =VLOOKUP(A:A,'Imprese_File completo'!M:M,1,FALSE) -> NGLCLD68M09H501R
A24: BSLGPP86T17L049K | B24: IT03900409S0001 | C24: BASILE | D24: GIUSEPPE | E24: M | F24: 17/12/1986 | G24: TA | H24: TARANTO | I24: IT | K24: VIA ALHAMBRA S.N.. | L24: 74010 | M24: STATTE | N24: TA | R24: 3884449888 | S24: giuseppebasile-86@outlook.it; | T24: - | U24: =VLOOKUP(A:A,'Imprese_File completo'!M:M,1,FALSE) -> BSLGPP86T17L049K
A25: BBTCRL71D30E158P | B25: IT03990F08S0001 | C25: ABBATE | D25: CARLO | E25: M | F25: 30/04/1971 | G25: CE | H25: GRAZZANISE | I25: IT | K25: TRAVERSA I DI VIA ALBERO LUNGO 11 | L25: 81046 | M25: GRAZZANISE | N25: CE | Q25: IT | R25: - | S25: - | T25: - | U25: =VLOOKUP(A:A,'Imprese_File completo'!M:M,1,FALSE) -> #N/A
A26: CHNSNJ63C47Z210Z | B26: IT039A000FS0001 | C26: CHEN | D26: SHENJUAN | E26: F | F26: 07/03/1963 | G26: E | H26: CINA | I26: CN | J26: CINA | K26: VIA ROMA 13 | L26: 26865 | M26: SAN ROCCO AL PORTO | N26: LO | Q26: IT | R26: 3661572683 | S26: susubarmazzini@gmail.com; | T26: chenshenjuan@pec.it | U26: =VLOOKUP(A:A,'Imprese_File completo'!M:M,1,FALSE) -> CHNSNJ63C47Z210Z
A27: LEIFNC77S48C978G | B27: IT03CC0C04S0001 | C27: ELIA | D27: FRANCESCA EMMA | E27: F | F27: 08/11/1977 | G27: LE | H27: COPERTINO | I27: IT | K27: VIA FRA FRANCESCO DA COPERTINO 6 | L27: 73043 | M27: COPERTINO | N27: LE | Q27: IT | R27: - | S27: - | T27: - | U27: =VLOOKUP(A:A,'Imprese_File completo'!M:M,1,FALSE) -> #N/A
A28: FSCNTN74D12D862N | B28: IT03CC0C04S0001 | C28: FIOSCHI | D28: ANTONIO | E28: M | F28: 12/04/1974 | G28: LE | H28: GALATINA | I28: IT | K28: VIA DI SANTA BARBARA SC | L28: 73043 | M28: COPERTINO | N28: LE | Q28: IT | R28: - | S28: - | T28: - | U28: =VLOOKUP(A:A,'Imprese_File completo'!M:M,1,FALSE) -> #N/A
A29: CRNGPP63P27D643F | B29: IT03CF070FS0001 | C29: CORNACCHIO | D29: GIUSEPPE | E29: M | F29: 27/09/1963 | G29: FG | H29: FOGGIA | I29: IT | K29: VIA TOSCANINI 2 | L29: 43029 | M29: TRAVERSETOLO | N29: PR | R29: 0521341225 - 3281783808 | S29: giuseppe_cornacchio@libero.it; | T29: tabaccheriacornacchio@pec.it | U29: =VLOOKUP(A:A,'Imprese_File completo'!M:M,1,FALSE) -> CRNGPP63P27D643F
A30: LRNFRC87C19H793T | B30: IT03E60D0AS0001 | C30: LORENZO | D30: FEDERICO | E30: M | F30: 19/03/1987 | G30: LE | H30: SAN CESARIO DI LECCE | I30: IT | K30: VIA UDINE 20 | L30: 73047 | M30: MONTERONI DI LECCE | N30: LE | Q30: IT | R30: 3387020417 - 3387020417 | S30: chico87lo@hotmail.it; | T30: - | U30: =VLOOKUP(A:A,'Imprese_File completo'!M:M,1,FALSE) -> LRNFRC87C19H793T
A31: BRRCMN68L55L528S | B31: IT03EF0709S0001 | C31: BERARDINELLI | D31: CARMEN | E31: F | F31: 15/07/1968 | G31: SV | H31: VADO LIGURE | I31: IT | K31: VIA VINCENZO BELLINI 3/11 | L31: 17100 | M31: SAVONA | N31: SV | R31: 019-4501359 - 3453259405 | S31: puntosnaisavona@libero.it; | T31: - | U31: =VLOOKUP(A:A,'Imprese_File completo'!M:M,1,FALSE) -> BRRCMN68L55L528S
A32: GMMGPP69D09H163L | B32: IT041C0C09S0001 | C32: GIUMMARRA | D32: GIUSEPPE | E32: M | F32: 09/04/1969 | G32: RG | H32: RAGUSA | I32: IT | K32: VIA IMERA 8 | L32: 97100 | M32: RAGUSA | N32: RG | R32: 0932654419 - 3928600133 | S32: 9351rg@gmail.com; | T32: giummarragiuseppe@pec.webexe.it | U32: =VLOOKUP(A:A,'Imprese_File completo'!M:M,1,FALSE) -> GMMGPP69D09H163L
A33: RLNVNT85D51H501Z | B33: IT041D0A09S0001 | C33: ORLANDI | D33: VALENTINA | E33: F | F33: 11/04/1985 | G33: RM | H33: ROMA | I33: IT | K33: VIA CAULONIA 16 | L33: 00183 | M33: ROMA | N33: RM | Q33: IT | R33: - | S33: - | T33: - | U33: =VLOOKUP(A:A,'Imprese_File completo'!M:M,1,FALSE) -> #N/A
A34: CRODNL90B26H501V | B34: IT045E0702S0001 | C34: CORI | D34: DANIELE | E34: M | F34: 26/02/1990 | G34: RM | H34: ROMA | I34: IT | K34: VIA PIETRAFERRAZZANA 33 | L34: 00131 | M34: ROMA | N34: RM | Q34: IT | R34: - | S34: - | T34: - | U34: =VLOOKUP(A:A,'Imprese_File completo'!M:M,1,FALSE) -> #N/A
A35: TLMNGL81L54A285Q | B35: IT045F0E02S0001 | C35: TOLMINO | D35: ANGELA | E35: F | F35: 14/07/1981 | G35: BT | H35: ANDRIA | I35: IT | K35: VIA ARDIGO' 7 | L35: 76123 | M35: ANDRIA | N35: BT | Q35: IT | R35: - | S35: - | T35: - | U35: =VLOOKUP(A:A,'Imprese_File completo'!M:M,1,FALSE) -> #N/A
A36: MNPRNT60E44F839T | B36: IT0494000FS0001 | C36: MINOPOLI | D36: RENATA | E36: F | F36: 04/05/1960 | G36: NA | H36: NAPOLI | I36: IT | K36: VIA AUGUSTO RIGHI 28 | L36: 80125 | M36: NAPOLI | N36: NA | Q36: IT | R36: 0810360381 - 3278267775 | S36: diocleziano248@libero.it; | T36: minopolirenata@pec.it | U36: =VLOOKUP(A:A,'Imprese_File completo'!M:M,1,FALSE) -> MNPRNT60E44F839T
A37: PCCMTN92P59G141H | B37: IT04E2080ES0001 | C37: PICCIANO | D37: MARTINA | E37: F | F37: 19/09/1992 | G37: CH | H37: ORTONA | I37: IT | K37: VIA ORNI 7 | L37: 66010 | M37: CANOSA SANNITA | N37: CH | R37: - | S37: martinapicciano@gmail.com; | T37: MARTINAPICCIANO@PEC.IT | U37: =VLOOKUP(A:A,'Imprese_File completo'!M:M,1,FALSE) -> PCCMTN92P59G141H
A38: PLVFNC86S20A056I | B38: IT050A0B0ES0001 | C38: PULVIRENTI | D38: FRANCESCO | E38: M | F38: 20/11/1986 | G38: CT | H38: ADRANO | I38: IT | K38: VIA DELLA 35 | L38: 95031 | M38: ADRANO | N38: CT | Q38: IT | R38: 0957692613 - 329-7884065 | S38: pulvirenti.francesco@hotmail.com; | T38: - | U38: =VLOOKUP(A:A,'Imprese_File completo'!M:M,1,FALSE) -> PLVFNC86S20A056I
A39: RLAFNC85H01A717T | B39: IT051E0B0AS0001 | C39: RAELE | D39: FRANCESCO | E39: M | F39: 01/06/1985 | G39: SA | H39: BATTIPAGLIA | I39: IT | K39: VIA CA' BERTACCHI 20/1 | L39: 42030 | M39: VIANO | N39: RE | Q39: IT | R39: 3347854638 | S39: frenzraele@yahoo.it; | T39: - | U39: =VLOOKUP(A:A,'Imprese_File completo'!M:M,1,FALSE) -> RLAFNC85H01A717T
A40: VRDRSO70T66B925K | B40: IT052C0E07S0001 | C40: VERDE | D40: ROSA | E40: F | F40: 26/12/1970 | G40: NA | H40: CASANDRINO | I40: IT | K40: VIA MONTESSORI 14 | L40: 81031 | M40: AVERSA | N40: CE | R40: - | S40: - | T40: - | U40: =VLOOKUP(A:A,'Imprese_File completo'!M:M,1,FALSE) -> VRDRSO70T66B925K
...

Sheet Imprese_File clean
A1: DATI SOCIETA' | X1: DATI RAPPRESENTANTE LEGALE | AM1: CONTATTI
A2: 99 | B2: RAGIONE SOCIALE | C2: _PIVA | D2: _CF | E2: SEDE | F2: Posizione incrociata | G2: Posizione Duplicata | H2: Crif Number | I2: Denominazione | J2: Partita Iva | K2: REA | L2: CCIAA | M2: Codice fiscale | N2: Indirizzo | O2: Cap | P2: Comune | Q2: Frazione | R2: Provincia | S2: Regione | T2: Stato Impresa Cribis | U2: Natura giuridica | V2: Tipo natura giuridica | W2: dummy1 | X2: Cognome Esponente | Y2: Nome Esponente | Z2: Sesso | AA2: Data di nascita | AB2: Provincia di Nascita | AC2: Comune di Nascita | AD2: Nazione di Nascita | AE2: Cittadinanza | AF2: Indirizzo RL | AG2: CAP RL | AH2: Comune RL | AI2: Provincia RL | AJ2: Frazione RL | AK2: Altre indicazioni | AL2: Nazione | AM2: Telefono | AN2: Email | AO2: PEC
A3: 99014890 | B3: BLACK CAFE' DI HU ZHIGE | C3: 02278450396 | D3: HUXZHG73T19Z210Q | F3: Y | H3: ITC7120F00S0001 | I3: BLACK CAFE' DI HU ZHIGE | J3: 02278450396 | K3: 288906 | L3: PV | M3: HUXZHG73T19Z210Q | N3: VIA GAMBOLINA 33 | O3: 27029 | P3: VIGEVANO | R3: PV | S3: LOMBARDIA | T3: Attiva | U3: IMPRESA INDIVIDUALE | V3: IMPRESE INDIVIDUALI | X3: HU | Y3: ZHIGE | Z3: M | AA3: 19/12/1973 | AB3: E | AC3: ZHEJIANG | AD3: CN | AE3: CINA | AF3: VIA AGUZZAFAME 61 | AG3: 27029 | AH3: VIGEVANO | AI3: PV | AJ3: 0 | AK3: 0 | AL3: IT | AM3: 3315003168 | AN3: 1017108343@qq.com; | AO3: -
A4: 99008465 | B4: HAPPY HOUR DI WU SHIJIN | C4: 02594430353 | D4: WUXSJN77E11Z210D | E4: VIA MATTEOTTI 29/B - 42048 RUBIERA RE | F4: Y | H4: ITABEB0B09S0001 | I4: HAPPY HOUR DI WU SHIJIN | J4: 02594430353 | K4: 296066 | L4: RE | M4: WUXSJN77E11Z210D | N4: VIA MATTEOTTI 29/B | O4: 42048 | P4: RUBIERA | R4: RE | S4: EMILIA-ROMAGNA | T4: Attiva | U4: IMPRESA INDIVIDUALE | V4: IMPRESE INDIVIDUALI | X4: WU | Y4: SHIJIN | Z4: M | AA4: 11/05/1977 | AB4: E | AC4: ZHEJIANG | AD4: CN | AE4: CINA | AF4: VIA FRATELLI ROSSELLI 1 | AG4: 42048 | AH4: RUBIERA | AI4: RE | AJ4: 0 | AK4: 0 | AL4: IT | AM4: 0522620048 - 3298482508 | AN4: 104190885@qq.com; | AO4: -
A5: 99015454 | B5: SALA SLOT ROYAL S.R.L. | C5: 02023600477 | D5: 02023600477 | E5: TOSCANA - 51100 PISTOIA | F5: Y | H5: ITA1DA0E04S0001 | I5: SALA SLOT ROYAL SRL | J5: 02023600477 | K5: 604510 | L5: PT | M5: 02023600477 | N5: VIA TOSCANA 124 | O5: 51100 | P5: PISTOIA | R5: PT | S5: TOSCANA | T5: Inattiva | U5: SOCIETA' A RESPONSABILITA' LIMITATA | V5: SOCIETA' DI CAPITALE | X5: JIANG | Y5: JIE | Z5: F | AA5: 02/04/1990 | AB5: E | AC5: CINA | AD5: CN | AE5: CINA | AF5: VIA ANGIOLO BADIANI 12 | AG5: 59100 | AH5: PRATO | AI5: PO | AJ5: 0 | AK5: 0 | AL5: IT | AM5: 3331226767 | AN5: 1135204976@QQ.COM; | AO5: -
A6: 99013944 | B6: LUCKY GAMES DI LIU FANGFANG & C. S.A.S. | C6: 02470750973 | D6: 02470750973 | E6: TOURCOING - 59100 PRATO | F6: Y | H6: IT46550E06S0001 | I6: LUCKY GAMES DI LIU FANGFANG & C. SAS | J6: 02470750973 | K6: 538764 | L6: PO | M6: 02470750973 | N6: VIA TOURCOING 35/4 | O6: 59100 | P6: PRATO | R6: PO | S6: TOSCANA | T6: Attiva | U6: SOCIETA' IN ACCOMANDITA SEMPLICE | V6: SOCIETA' DI PERSONE | X6: LIU | Y6: FANGFANG | Z6: F | AA6: 27/01/1982 | AB6: E | AC6: ZHEJIANG | AD6: CN | AE6: CINA | AF6: VIA AIETTA 20 | AG6: 59016 | AH6: POGGIO A CAIANO | AI6: PO | AJ6: 0 | AK6: 0 | AL6: IT | AM6: 3331226767 | AN6: 1135204976@qq.com; | AO6: -
A7: 99008537 | B7: ZHANG XIANGYANG | C7: 03063650125 | D7: ZHNXGY77P21Z210R | E7: Via Degli Arrotini, 9 - 25016 GHEDI | F7: Y | H7: IT7818090AS0001 | I7: SALA VLT 168 DI ZHANG XIANGYANG | J7: 03063650125 | K7: 521553 | L7: PO | M7: ZHNXGY77P21Z210R | N7: VIA LIGURIA 6/5 | O7: 59100 | P7: PRATO | R7: PO | S7: TOSCANA | T7: Attiva | U7: IMPRESA INDIVIDUALE | V7: IMPRESE INDIVIDUALI | X7: ZHANG | Y7: XIANGYANG | Z7: M | AA7: 21/09/1977 | AB7: E | AC7: ZHEJIANG | AD7: CN | AE7: CINA | AF7: VIA FABIO FILZI 116 | AG7: 59100 | AH7: PRATO | AI7: PO | AJ7: 0 | AK7: 0 | AL7: IT | AM7: 3331226767 | AN7: 1135204976@qq.com; | AO7: -
A8: 99001076 | B8: TABACCHERIA ORSINI TIZIANA | C8: 01450380686 | D8: RSNTZN73A43L186L | E8: VIA VESTINA 152 - 65016 MONTESILVANO PE | F8: Y | H8: ITB8640602S0001 | I8: ORSINI TIZIANA | J8: 01450380686 | K8: 101847 | L8: PE | M8: RSNTZN73A43L186L | N8: VIA VESTINA 152 | O8: 65015 | P8: MONTESILVANO | R8: PE | S8: ABRUZZO | T8: Attiva | U8: IMPRESA INDIVIDUALE | V8: IMPRESE INDIVIDUALI | X8: ORSINI | Y8: TIZIANA | Z8: F | AA8: 03/01/1973 | AB8: PE | AC8: TOCCO DA CASAURIA | AD8: IT | AE8: 0 | AF8: VIA RIGOPIANO 173/7 | AG8: 65124 | AH8: PESCARA | AI8: PE | AJ8: 0 | AK8: 0 | AL8: 0 | AM8: 0854680144 | AN8: tizianaorsini99@tiscali.it; | AO8: 0010021530001@postacertificata.tabaccai.it
A9: 99000841 | B9: CARESTIA ANTONIO | C9: 01284980685 | D9: CRSNTN68B19G482R | E9: c/so Primo Maggio 141/143 - 65027 Scafa PE | F9: Y | H9: IT8B4F0909S0001 | I9: CARESTIA ANTONIO | J9: 01284980685 | K9: 90053 | L9: PE | M9: CRSNTN68B19G482R | N9: CORSO I MAGGIO 141/143 | O9: 65027 | P9: SCAFA | R9: PE | S9: ABRUZZO | T9: Attiva | U9: IMPRESA INDIVIDUALE | V9: IMPRESE INDIVIDUALI | X9: CARESTIA | Y9: ANTONIO | Z9: M | AA9: 19/02/1968 | AB9: PE | AC9: PESCARA | AD9: IT | AE9: 0 | AF9: VIA BOLOGNA 13 | AG9: 65027 | AH9: SCAFA | AI9: PE | AJ9: 0 | AK9: 0 | AL9: IT | AM9: 0858542105 - 0858542105 | AN9: antonio.carestia68@gmail.com; | AO9: 0010312280001@postacertificata.tabaccai.it
A10: 99001601 | B10: MARCO LERA | C10: 01847300462 | D10: LREMRC71D23E715R | E10: VIA DELLE VILLE 67/A - 55013 LAMMARI LU | F10: Y | H10: IT6500070ES0001 | I10: LERA MARCO | J10: 01847300462 | K10: 177009 | L10: LU | M10: LREMRC71D23E715R | N10: VIA DELLE VILLE 67/A | O10: 55012 | P10: CAPANNORI | Q10: LAMMARI | R10: LU | S10: TOSCANA | T10: Attiva | U10: IMPRESA INDIVIDUALE | V10: IMPRESE INDIVIDUALI | X10: LERA | Y10: MARCO | Z10: M | AA10: 23/04/1971 | AB10: LU | AC10: LUCCA | AD10: IT | AE10: 0 | AF10: VIA LOMBARDA 145 LAMMARI | AG10: 55012 | AH10: CAPANNORI | AI10: LU | AJ10: 0 | AK10: 0 | AL10: 0 | AM10: 0583961657 | AN10: ricevitoria.osteria@libero.it; | AO10: 0010373400001@postacertificata.tabaccai.it
A11: 99007528 | B11: MARTINO 2000 | C11: 02359340961 | D11: RGGCDM57E22D231T | E11: VIALE COOPERAZIONE, 43 - 20095 CUSANO MILANINO | F11: Y | H11: ITBE86070DS0001 | I11: MARTINO 2000 | J11: 02359340961 | K11: 1439199 | L11: MI | M11: RGGCDM57E22D231T | N11: VIALE COOPERAZIONE 54 | O11: 20095 | P11: CUSANO MILANINO | R11: MI | S11: LOMBARDIA | T11: Attiva | U11: IMPRESA INDIVIDUALE | V11: IMPRESE INDIVIDUALI | X11: ORIGGI | Y11: CLAUDIO MARIA | Z11: M | AA11: 22/05/1957 | AB11: MI | AC11: CUSANO MILANINO | AD11: IT | AE11: 0 | AF11: VIA CARLO IMBONATI 62/2 | AG11: 20159 | AH11: MILANO | AI11: MI | AJ11: 0 | AK11: 0 | AL11: IT | AM11: 0266401122 - 3355202677 | AN11: claudio@martino2000.it; | AO11: 0010398410001@POSTACERTIFICATA.TABACCAI.IT; fe.dylogbuffetti@sicurezzapostale.it
A12: 99000759 | B12: CERQUA MASSIMILIANOTABACCHERIA RIV. | C12: 01218970505 | D12: CRQMSM72M03B950G | E12: PIAZZA MAZZINI 14 - 50010 MIGLIARINO PISANO PI | F12: Y | H12: IT69C40105S0001 | I12: CERQUA MASSIMILIANO | J12: 01218970505 | K12: 108217 | L12: PI | M12: CRQMSM72M03B950G | N12: PIAZZA GIUSEPPE MAZZINI 12 | O12: 56019 | P12: VECCHIANO | R12: PI | S12: TOSCANA | T12: Attiva | U12: IMPRESA INDIVIDUALE | V12: IMPRESE INDIVIDUALI | X12: CERQUA | Y12: MASSIMILIANO | Z12: M | AA12: 03/08/1972 | AB12: PI | AC12: CASCINA | AD12: IT | AE12: 0 | AF12: VIA CHARLES DARWIN 2 ARENA METATO | AG12: 56017 | AH12: SAN GIULIANO TERME | AI12: PI | AJ12: 0 | AK12: 0 | AL12: 0 | AM12: 050803320 - 3488235512 | AN12: maxcerqua@yahoo.it; | AO12: 0020046200001@POSTACERTIFICATA.TABACCAI.IT

Sheet voucher
A1: voucher | B1: partita iva (account/codice sap) | C1: rappresentante legale | D1: pec | E1: telefono | F1: data invio | G1: data attivazione | H1: stato
A2: WS935-QA8WE2WTQH
A3: WS935-4VXQ6AJY6L
A4: WS935-LCFJUDG4TW
A5: WS935-KRGH9EIP9C
A6: WS935-TJLAYIGDPM
A7: WS935-138C8N1DK5
A8: WS935-OLCPVVB6WC
A9: WS935-CAC1W7UVUK
A10: WS935-OWU0STYO2G
A11: WS935-AXQ1NX45SQ
A12: WS935-90VM68BAUF
A13: WS935-6Q21QYPVEB
... A1738: WS935-TBYTYKJ9NJ

Sheet Giacomo1
A1: EMAIL | B1: PEC | C1: VOUCHER
B2: 0022156710001@postacertificata.tabaccai.it | C2: WS935-M2X6XX9519
B3: 7stellesas@pec.it | C3: WS935-XBGV3XK9CN
B4: abelloplay@pec.it | C4: WS935-9C0S4S6Y2I
B5: BAR.ITALIA_SNC@PEC.IT | C5: WS935-RMV6PQKJT0
B6: CAMPI.FLAVIO@LEGALMAIL.IT | C6: WS935-E0D89UCEX5
B7: catalanofrancesco84@pec.it | C7: WS935-FVSVVCPB2X
B8: ciampisnc@sicurezzapostale.it | C8: WS935-RKQ9IM3QHC
B9: CICABETSRL@LEGALMAIL.IT | C9: WS935-Y60X3X6V76
B10: dega@legalmail.it | C10: WS935-TRR15J9AE8
B11: depalmavincenzo88@pec.it | C11: WS935-PAR03FBTXF
B12: F.CARACCI77@ARUBAPEC.IT | C12: WS935-D2EC7YA916
B13: f.llilamasrls@pec.it | C13: WS935-O2GM3UMXIU
... B44: TOTALGEST@LEGALMAIL.IT | C44: WS935-VX118U6O7N
A45: 0245486444@fastwebnet.it | B45: BIEMME@PECIMPRESE.IT | C45: WS935-JOX4Y0WHE2
A46: 1017108343@qq.com | C46: WS935-QA8WE2WTQH
A47: 104190885@qq.com | C47: WS935-4VXQ6AJY6L
A48: 1135204976@QQ.COM | C48: WS935-KRGH9EIP9C
A49: 1135204976@qq.com | C49: WS935-TJLAYIGDPM
A50: 1135204976@qq.com | C50: WS935-OWU0STYO2G
A51: 1692774133@qq.com | C51: WS935-90VM68BAUF
A52: 2015magiasrl@gmail.com | B52: 2015MAGIASRL@PEC.IT | C52: WS935-WTTSQYH36D
A53: 3358186977@virgilio.it | B53: ALMASRL@LEGALPEC.ME | C53: WS935-H6T2RBHHGY
A54: 3lettie@tiscali.it | B54: PUNTOSNAI.VENTIMIGLIA@LEGALMAIL.IT | C54: WS935-UDRPKO826N
A55: 443447131@qq.com | C55: WS935-SEPTWDG815
A56: 48581587@qq.com | C56: WS935-6Q21QYPVEB
A57: 4winsrl@gmail.com | B57: 4WINSRL@LEGALMAIL.IT | C57: WS935-44AU5455YR
A58: 510658306@qq.com | C58: WS935-JE5EME3G10
A59: 51mtoro@libero.it | C59: WS935-3L2V6A6W8U
A60: 525215546@qq.com | C60: WS935-MWW6XUXWC0
A61: 6unica1@virgilio.it | B61: VANNI.MIRKO@LEGALMAIL.IT | C61: WS935-OH5IX5QSFA
A62: 88huanglihong@gmail.com | B62: huanglihong@pec.it | C62: WS935-U9NYRJ231D
A63: 8games@tiscali.it | B63: 8GAMESSRL@LEGALMAIL.IT | C63: WS935-WV8HIVXCYX
A64: 9351rg@gmail.com | B64: giummarragiuseppe@pec.webexe.it | C64: WS935-OSKR5816HP
A65: a.tagliasacchi@alice.it | B65: MINIBARSNC@LEGALMAIL.IT | C65: WS935-GC2GDXY9J4
A66: a3880557673@gmail.com | B66: allpubsnc@pec.it | C66: WS935-BR1OF7M4M9
A67: achilleesposito@hotmail.it | C67: WS935-W53YJ9T3M9
A68: adamofilippo@libero.it | B68: ROYALPLANET@PEC.IT | C68: WS935-SVTVXM26T8
A69: adele.guerriero@libero.it | C69: WS935-S6N7XLW0PW
A70: adm_csnai@yahoo.it | B70: GOODLUCKSRL@PEC.IT | C70: WS935-BWSKXNOV81
...

Sheet Giacomo2
A1: EMAIL | B1: VOUCHER
A2: 0010021530001@postacertificata.tabaccai.it | B2: WS935-QC6LBBBVJ1
A3: 0010312280001@postacertificata.tabaccai.it | B3: WS935-SQSVPXGISA
A4: 0010373400001@postacertificata.tabaccai.it | B4: WS935-854QP5NAK5
A5: 0010398410001@POSTACERTIFICATA.TABACCAI.IT | B5: WS935-7JDAHA1OXU
A6: 0020046200001@POSTACERTIFICATA.TABACCAI.IT | B6: WS935-S6T3E94B2X
A7: 0020067730001@POSTACERTIFICATA.TABACCAI.IT | B7: WS935-X93Q7QLURI
A8: 0020117990001@postacertificata.tabaccai.it | B8: WS935-XUV8EVBCIW
A9: 0020149420001@postacertificata.tabaccai.it | B9: WS935-1IE66BJF7W
A10: 0020259480001@postacertificata.tabaccai.it | B10: WS935-BVIQLL6RX1
A11: 0020552590001@postacertificata.tabaccai.it | B11: WS935-UTLBMYQY6W
A12: 0020681610001@postacertificata.tabaccai.it | B12: WS935-TY57A9S5DA
... A1738: zzyfran@gmail.com | B1738: WS935-RJMJTUYVRS
